Workbook
Name \a: #REF!
Name \b: #REF!
Name \c: #REF!
Name \d: #REF!
Name \e: #REF!
Name \f: #REF!
Name \g: #REF!
Name \h: #REF!
Name \i: #REF!
Name \j: #REF!
Name \k: #REF!
Name \l: #REF!
Name \m: #REF!
Name \n: #REF!
Name \o: #REF!
Name \p: #REF!
Name \q: #REF!
Name \r: #REF!
Name \s: #REF!
Name \t: #REF!
Name \u: #REF!
Name \v: #REF!
Name \w: #REF!
Name \x: #REF!
Name \Y: #REF!
Name \z: #REF!
Name ______________________________________________________________________________R: #REF!
Name ______________________________________________________________________________rad2: #REF!
Name _____________________________________________________________________________R: #REF!
Name _____________________________________________________________________________rad2: #REF!
Name ____________________________________________________________________________R: #REF!
Name ____________________________________________________________________________rad2: #REF!
Name ___________________________________________________________________________R: #REF!
Name ___________________________________________________________________________rad2: #REF!
Name __________________________________________________________________________R: #REF!
Name __________________________________________________________________________rad2: #REF!
Name _________________________________________________________________________R: #REF!
Name _________________________________________________________________________rad2: #REF!
Name ________________________________________________________________________R: #REF!
Name ________________________________________________________________________rad2: #REF!
Name _______________________________________________________________________R: #REF!
Name _______________________________________________________________________rad2: #REF!
Name ______________________________________________________________________R: #REF!
Name ______________________________________________________________________rad2: #REF!
Name _____________________________________________________________________R: #REF!
Name _____________________________________________________________________rad2: #REF!
Name ____________________________________________________________________R: #REF!
Name ____________________________________________________________________rad2: #REF!
Name ___________________________________________________________________R: #REF!
Name ___________________________________________________________________rad2: #REF!
Name __________________________________________________________________R: #REF!
Name __________________________________________________________________rad2: #REF!
Name _________________________________________________________________R: #REF!
Name _________________________________________________________________rad2: #REF!
Name ________________________________________________________________rad2: #REF!
Name ____________________________________OP9: #REF!
Name ___________________________________OP9: #REF!
Name __________________________________OP9: #REF!
Name ________________________GYE1: #REF!
Name ________________________gye2: #REF!

Sheet FLOW MEDIOS
E3: FLOW DE MEDIOS
E4: CAMPAÑA VAC COSTA 2026
E6: 2026
E7: ENERO | I7: FEBRERO | M7: MARZO | R7: ABRIL | Z7: DETALLE DE INVERSIÓN | AC7: DETALLE DE COMPRA
E8: 5 | F8: 12 | G8: 19 | H8: =G8+7 -> 26 | I8: 2 | J8: =I8+7 -> 9 | K8: =J8+7 -> 16 | L8: =K8+7 -> 23 | M8: 2 | N8: =M8+7 -> 9 | O8: =N8+7 -> 16 | P8: =O8+7 -> 23 | Q8: =P8+7 -> 30 | R8: 6 | S8: =R8+7 -> 13 | T8: =S8+7 -> 20 | U8: =T8+7 -> 27 | V8: =U8+7 -> 34 | X8: TOTAL INVERSIÓN | Z8: MARKETING | AA8: NEGOCIO | AC8: PAUTA PAGADA | AD8: PREPAGO | AE8: COMPROMISOS
D9: LAYER 01 AWARENESS
D10: TELEVISIÓN | X10: =SUM(E11:Q12) -> 45620
D11: PAUTA REGULAR - ECUAVISA | E11: =+'PAUTA TELEVISIÓN OP2'!CT19+'PAUTA TELEVISIÓN OP2'!CT54 -> 10186.23 | I11: =+'PAUTA TELEVISIÓN OP2'!CU19+'PAUTA TELEVISIÓN OP2'!CU54 -> 17413.77 | Z11: =SUM(E11:Q11) -> 27600 | AC11: =SUM(D11:P11) -> 27600
D12: PAUTA REGULAR - TC TELEVISIÓN | E12: =+'PAUTA TELEVISIÓN OP2'!CT75 -> 9247.9967 | I12: =+'PAUTA TELEVISIÓN OP2'!CU75 -> 8772.0033 | Z12: =SUM(E12:Q12) -> 18020 | AC12: =SUM(D12:P12) -> 18020
D13: VÍA PÚBLICA | X13: =SUM(E14:Q17) -> 13000
D14: VALLAS | E14: =+'PAUTA VALLAS'!Q30 -> 8600 | I14: 0 | Z14: =SUM(E14:Q14) -> 8600 | AC14: =SUM(E14:Q14) -> 8600
D15: CIRCUITO VIA LA COSTA | E15: =+'CIRCUITO VIA LA COSTA'!N11 -> 4400 | I15: 0 | Z15: =SUM(E15:Q15) -> 4400 | AC15: =SUM(E15:Q15) -> 4400
D16: PANTALLAS LEDS | E16: 0 | I16: 0 | Z16: =SUM(E16:Q16) -> 0 | AC16: =SUM(E16:Q16) -> 0
D17: VALLAS HIBRIDAS | E17: 0 | I17: 0 | Z17: =SUM(E17:Q17) -> 0 | AC17: =SUM(E17:Q17) -> 0
D18: REVISTAS | X18: 0
D19: REVISTA DINERS | I19: 0 | Z19: =SUM(E19:Q19) -> 0 | AC19: =SUM(E19:Q19) -> 0
D20: DIGITAL | X20: =SUM(E21:Q24) -> 7500
D21: META | E21: =+'PAUTA DIGITAL'!AB14+'PAUTA DIGITAL'!AB15 -> 1140 | I21: =+'PAUTA DIGITAL'!AI14+'PAUTA DIGITAL'!AI15 -> 760 | Z21: =+E21+I21 -> 1900 | AC21: =+Z21 -> 1900
D22: TIK TOK | E22: =+'PAUTA DIGITAL'!AB16+'PAUTA DIGITAL'!AB17 -> 360 | I22: =+'PAUTA DIGITAL'!AI16+'PAUTA DIGITAL'!AI17 -> 240 | Z22: =+E22+I22 -> 600 | AC22: =+Z22 -> 600
D23: YOUTUBE | E23: =+'PAUTA DIGITAL'!AB18+'PAUTA DIGITAL'!AB19+'PAUTA DIGITAL'!AB20+'PAUTA DIGITAL'!AB21 -> 600 | I23: =+'PAUTA DIGITAL'!AI18+'PAUTA DIGITAL'!AI19+'PAUTA DIGITAL'!AI20+'PAUTA DIGITAL'!AI21 -> 400 | Z23: =+E23+I23 -> 1000 | AC23: =+Z23 -> 1000
D24: DV360 | E24: =+'PAUTA DIGITAL'!AB22 -> 2400 | I24: =+'PAUTA DIGITAL'!AI22 -> 1600 | Z24: =+E24+I24 -> 4000 | AD24: =+Z24 -> 4000
D26: SUBTOTAL | E26: =SUM(E11:H12,E14:H16,E21:H24) -> 36934.227 | I26: =SUM(I11:L12,I14:L16,I21:L24) -> 29185.773 | M26: =SUM(M11:Q11,M14:Q16,M21:Q24) -> 0 | R26: =SUM(R11:V11,R14:V16,R21:V24) -> 0 | X26: =SUM(X10:X20) -> 66120 | Z26: =SUM(Z11:Z24) -> 66120 | AA26: =SUM(AA11:AA24) -> 0 | AC26: =SUM(AC11:AC24) -> 62120 | AD26: =SUM(AD11:AD24) -> 4000 | AE26: =SUM(AE11:AE24) -> 0
D28: LAYER 02 CONSIDERACION
D29: DIGITAL | X29: =SUM(E30:Q32) -> 10363.9
D30: META | E30: ='[3]PAUTA DIGITAL'!AB24+'[3]PAUTA DIGITAL'!AB25+'[3]PAUTA DIGITAL'!AB26+'[3]PAUTA DIGITAL'!AB27+'[3]PAUTA DIGITAL'!AB32+'[3]PAUTA DIGITAL'!AB33+'[3]PAUTA DIGITAL'!AB34+'[3]PAUTA DIGITAL'!AB35+'[3]PAUTA DIGITAL'!AB40+'[3]PAUTA DIGITAL'!AB41+'[3]PAUTA DIGITAL'!AB42+'[3]PAUTA DIGITAL'!AB43 -> 1236.141 | I30: ='[3]PAUTA DIGITAL'!AG24+'[3]PAUTA DIGITAL'!AG25+'[3]PAUTA DIGITAL'!AG26+'[3]PAUTA DIGITAL'!AG27+'[3]PAUTA DIGITAL'!AG32+'[3]PAUTA DIGITAL'!AG33+'[3]PAUTA DIGITAL'!AG34+'[3]PAUTA DIGITAL'!AG35+'[3]PAUTA DIGITAL'!AG40+'[3]PAUTA DIGITAL'!AG41+'[3]PAUTA DIGITAL'!AG42+'[3]PAUTA DIGITAL'!AG43 -> 3090.3525 | M30: ='[3]PAUTA DIGITAL'!BI24+'[3]PAUTA DIGITAL'!BI25+'[3]PAUTA DIGITAL'!BI26+'[3]PAUTA DIGITAL'!BI27+'[3]PAUTA DIGITAL'!BI32+'[3]PAUTA DIGITAL'!BI33+'[3]PAUTA DIGITAL'!BI34+'[3]PAUTA DIGITAL'!BI35+'[3]PAUTA DIGITAL'!BI40+'[3]PAUTA DIGITAL'!BI41+'[3]PAUTA DIGITAL'!BI42+'[3]PAUTA DIGITAL'!BI43 -> 1854.2115 | Z30: =+'[4]PAUTA DIGITAL'!L24+'[4]PAUTA DIGITAL'!L25+'[4]PAUTA DIGITAL'!L26+'[4]PAUTA DIGITAL'!L27+'[4]PAUTA DIGITAL'!L34 -> 2230.2663 | AA30: =+'[4]PAUTA DIGITAL'!M34+'[4]PAUTA DIGITAL'!M35+'[4]PAUTA DIGITAL'!M36+'[4]PAUTA DIGITAL'!M37+'[4]PAUTA DIGITAL'!M44+'[4]PAUTA DIGITAL'!M45+'[4]PAUTA DIGITAL'!M46+'[4]PAUTA DIGITAL'!M47 -> 4099.9327 | AC30: =+Z30+AA30 -> 6330.199
D31: YOUTUBE | E31: ='[3]PAUTA DIGITAL'!AB30+'[3]PAUTA DIGITAL'!AB31+'[3]PAUTA DIGITAL'!AB38+'[3]PAUTA DIGITAL'!AB39+'[3]PAUTA DIGITAL'!AB46+'[3]PAUTA DIGITAL'!AB47 -> 189.47907 | I31: ='[3]PAUTA DIGITAL'!AG47+'[3]PAUTA DIGITAL'!AG46+'[3]PAUTA DIGITAL'!AG39+'[3]PAUTA DIGITAL'!AG38+'[3]PAUTA DIGITAL'!AG31+'[3]PAUTA DIGITAL'!AG30 -> 473.69766 | M31: ='[3]PAUTA DIGITAL'!BI47+'[3]PAUTA DIGITAL'!BI46+'[3]PAUTA DIGITAL'!BI38+'[3]PAUTA DIGITAL'!BI39+'[3]PAUTA DIGITAL'!BI30+'[3]PAUTA DIGITAL'!BI31 -> 284.2186 | Z31: =+'[4]PAUTA DIGITAL'!L30+'[4]PAUTA DIGITAL'!L31+'[4]PAUTA DIGITAL'!L32+'[4]PAUTA DIGITAL'!L33 -> 497.15549 | AA31: =+'[4]PAUTA DIGITAL'!M40+'[4]PAUTA DIGITAL'!M41+'[4]PAUTA DIGITAL'!M42+'[4]PAUTA DIGITAL'!M43+'[4]PAUTA DIGITAL'!M50+'[4]PAUTA DIGITAL'!M51+'[4]PAUTA DIGITAL'!M52+'[4]PAUTA DIGITAL'!M53 -> 994.31099 | AC31: =+Z31+AA31 -> 1491.4665
D32: TIKTOK | E32: ='[3]PAUTA DIGITAL'!AB45+'[3]PAUTA DIGITAL'!AB44+'[3]PAUTA DIGITAL'!AB37+'[3]PAUTA DIGITAL'!AB36+'[3]PAUTA DIGITAL'!AB29+'[3]PAUTA DIGITAL'!AB28 -> 647.15992 | I32: ='[3]PAUTA DIGITAL'!AG28+'[3]PAUTA DIGITAL'!AG29+'[3]PAUTA DIGITAL'!AG36+'[3]PAUTA DIGITAL'!AG37+'[3]PAUTA DIGITAL'!AG44+'[3]PAUTA DIGITAL'!AG45 -> 1617.8998 | M32: ='[3]PAUTA DIGITAL'!BI45+'[3]PAUTA DIGITAL'!BI44+'[3]PAUTA DIGITAL'!BI36+'[3]PAUTA DIGITAL'!BI37+'[3]PAUTA DIGITAL'!BI28+'[3]PAUTA DIGITAL'!BI29 -> 970.73987 | Z32: =+'[4]PAUTA DIGITAL'!L28+'[4]PAUTA DIGITAL'!L29 -> 645.73324 | AA32: =+'[4]PAUTA DIGITAL'!M38+'[4]PAUTA DIGITAL'!M39+'[4]PAUTA DIGITAL'!M48+'[4]PAUTA DIGITAL'!M49 -> 1291.4665 | AC32: =+Z32+AA32 -> 1937.1997
D34: SUBTOTAL | E34: =SUM(E30:H33) -> 2072.78 | I34: =SUM(I30:L33) -> 5181.9499 | M34: =SUM(M30:Q33) -> 3109.17 | R34: =SUM(R30:V33) -> 0 | X34: =SUM(X29:X29) -> 10363.9 | Z34: =SUM(Z29:Z32) -> 3373.1551 | AA34: =SUM(AA29:AA32) -> 6385.7101 | AC34: =SUM(AC29:AC32) -> 9758.8652 | AD34: =SUM(AD29:AD32) -> 0 | AE34: =SUM(AE29:AE32) -> 0
D36: LAYER 03 MOVILIZACION
D37: DIGITAL | X37: =SUM(E38:V39) -> 11853
D38: META | I38: =+'[4]PAUTA DIGITAL'!AF63+'[4]PAUTA DIGITAL'!AF65+'[4]PAUTA DIGITAL'!AF67 -> 2151 | M38: =+'[4]PAUTA DIGITAL'!BH63+'[4]PAUTA DIGITAL'!BH65+'[4]PAUTA DIGITAL'!BH67 -> 2151 | R38: =+'[4]PAUTA DIGITAL'!CM63+'[4]PAUTA DIGITAL'!CM65+'[4]PAUTA DIGITAL'!CM67 -> 2151 | AA38: =+I38+M38+R38 -> 6453 | AC38: =+AA38 -> 6453
D39: GOOGLE | I39: =+'[4]PAUTA DIGITAL'!AF64+'[4]PAUTA DIGITAL'!AF66+'[4]PAUTA DIGITAL'!AF68 -> 1800 | M39: =+'[4]PAUTA DIGITAL'!BH64+'[4]PAUTA DIGITAL'!BH66+'[4]PAUTA DIGITAL'!BH68 -> 1800 | R39: =+'[4]PAUTA DIGITAL'!CM64+'[4]PAUTA DIGITAL'!CM66+'[4]PAUTA DIGITAL'!CM68 -> 1800 | AA39: =+I39+M39+R39 -> 5400 | AC39: =+AA39 -> 5400
D41: APP BLU
D42: DIGITAL | X42: =SUM(E43:V43) -> 20.355
D43: META | I43: =+'PAUTA DIGITAL'!AT76+'PAUTA DIGITAL'!AT77+'PAUTA DIGITAL'!AT78+'PAUTA DIGITAL'!AT79 -> 6.785 | M43: =+'PAUTA DIGITAL'!BK76+'PAUTA DIGITAL'!BK77+'PAUTA DIGITAL'!BK78+'PAUTA DIGITAL'!BK79 -> 6.785 | R43: =+'PAUTA DIGITAL'!CP76+'PAUTA DIGITAL'!CP77+'PAUTA DIGITAL'!CP78+'PAUTA DIGITAL'!CP79 -> 6.785 | AA43: =+I43+M43+R43 -> 20.355 | AC43: =+AA43 -> 20.355
D45: DE UNA
D46: DIGITAL | X46: =SUM(E47:V48) -> 795.6095
D47: META | I47: =+'PAUTA DIGITAL'!N81 -> 499.1 | AA47: =+I47+M47+R47 -> 499.1 | AC47: =+AA47 -> 499.1
D48: GOOGLE | I48: =+'PAUTA DIGITAL'!N82 -> 296.5095 | AA48: =+I48+M48+R48 -> 296.5095 | AC48: =+AA48 -> 296.5095
D50: SUBTOTAL | E50: =SUM(E39:H44) -> 0 | I50: =SUM(I38:L48) -> 4753.3945 | M50: =SUM(M43:Q49) -> 6.785 | R50: =SUM(R43:V49) -> 6.785 | X50: =SUM(X37:X46) -> 12668.965 | Z50: =SUM(Z37:Z48) -> 0 | AA50: =SUM(AA37:AA48) -> 12668.965 | AC50: =SUM(AC37:AC48) -> 12668.965 | AD50: =SUM(AD37:AD39) -> 0 | AE50: =SUM(AE37:AE39) -> 0
...

Sheet PAUTA DIGITAL
C3: JOB | D3: DCEEA5A10068
C4: MKT | D4: MKT0022145 | E4: MKT0022086
C5: RESPONSABLE MLD | D5: CRISTIAN TAPIA
C6: RESPONSABLE DCE | D6: FERNANDO VILLACIS
C7: CLIENTE: | D7: DINERS CLUB DEL ECUADOR | R7: =ED14+ED15 -> 946.0705
C8: PRODUCTO: | D8: INSTITUCIONAL | R8: =R14+R15 -> 1900
C9: CAMPAÑA: | D9: VAC COSTA 2026
P10: 2285.71 | R10: =R8-R7 -> 953.9295
C12: =D9 -> VAC COSTA 2026 | T12: ENERO | AI12: FEBRERO | BK12: MARZO | CP12: ABRIL | DW12: KPI | DZ12: MONITOREO
C13: ETAPA | D13: SUB ETAPA | E13: MEDIO | F13: FORMATO | G13: MENSAJE | H13: SEGMENTACIÓN | I13: TAMAÑO AUDIENCIA | J13: TIPO DE COMPRA | K13: SHARE | L13: =+E4 -> MKT0022086 | M13: =+D4 -> MKT0022145 | N13: INVERSIÓN | O13: PLATAFORMA | P13: REAL EJECUTADO ENERO | R13: ORIGINAL | S13: Plat. | T13: 16 | U13: 17 | V13: 18 | W13: 19 | X13: 20 | Y13: 21 | Z13: 22 | AA13: 23 | AB13: 24 | AC13: 25 | AD13: 26 | AE13: 27 | AF13: 28 | AG13: 29 | AH13: 30 | AI13: 1 | AJ13: 2 | AK13: 3 | AL13: 4 | AM13: 5 | AN13: 6 | AO13: 7 | AP13: 8 | AQ13: 9 | AR13: 10 | AS13: 11 | AT13: 12 | AU13: 13 | AV13: 14 | AW13: 15 | AX13: 16 | AY13: 17 | AZ13: 18 | BA13: 19 | BB13: 20 | BC13: 21 | BD13: 22 | BE13: 23 | BF13: 24 | BG13: 25 | BH13: 26 | BI13: 27 | BJ13: 28 | BK13: 1 | BL13: 2 | BM13: 3 | BN13: 4 | BO13: 5 | BP13: 6 | BQ13: 7 | BR13: 8 | BS13: 9 | BT13: 10 | BU13: 11 | BV13: 12 | BW13: 13 | BX13: 14 | BY13: 15 | BZ13: 16 | CA13: 17 | CB13: 18 | CC13: 19 | CD13: 20 | CE13: 21 | CF13: 22 | CG13: 23 | CH13: 24 | CI13: 25 | CJ13: 26 | CK13: 27 | CL13: 28 | CM13: 29 | CN13: 30 | CO13: 31 | CP13: 1 | CQ13: 2 | CR13: 3 | CS13: 4 | CT13: 5 | CU13: 6 | CV13: 7 | CW13: 8 | CX13: 9 | CY13: 10 | CZ13: 11 | DA13: 12 | DB13: 13 | DC13: 14 | DD13: 15 | DE13: 16 | DF13: 17 | DG13: 18 | DH13: 19 | DI13: 20 | DJ13: 21 | DK13: 22 | DL13: 23 | DM13: 24 | DN13: 25 | DO13: 26 | DP13: 27 | DQ13: 28 | DR13: 29 | DS13: 30 | DT13: FRECUENCIA MÁXIMA | DU13: ALCANCE ESTIMADO PERSONAS | DV13: ALCANCE ESTIMADO COBERTURA | DW13: Costo | DX13: Objetivo | DZ13: IMPORTE GASTADO | EA13: REMANENTE | EB13: AVANCE PPTO | EC13: FECHA MONITOREO | ED13: REAL CUMPLIDO | EE13: TIPO DE COMPRA | EF13: AVANCE OBJETIVOS | EG13: RESULTADOS | EH13: COSTO POR RESULTADO | EI13: CPV | EJ13: CPC | EK13: CPM | EL13: ALCANCE | EM13: FREC | EN13: CLICS | EO13: THRU´PLAYS | EP13: IMPRESIONES | EQ13: CTR | ER13: VTR | ES13: NOMBRE DE CAMPAÑA | ET13: ESTADO DE LA CAMPAÑA | EU13: BASES | EV13: UTM
C14: LAYER 01 AWARENESS | D14: LANZAMIENTO | E14: META | F14: PROMOTED VIDEO | G14: Video hero posicionamiento con experiencias únicas generación de interés en Alto Valor | H14: BASE SOCIOS DINERS REGION COSTA | I14: 266000 | J14: CPM | K14: =+N14/$N$84 -> 0.039301911 | L14: =+N14 -> 1200 | N14: 1200 | O14: =+N14/1.15 -> 1043.4783 | P14: 206.97 | R14: 1200 | AB14: =+N14*60% -> 720 | AI14: =+N14*40% -> 480 | DU14: =358000*55% -> 196900 | DV14: 0.59 | DW14: 0.05 | DX14: =O14/DW14*1000 -> 20869565 | DZ14: 519.03 | EA14: =+O14-DZ14 -> 524.44826 | EB14: =+DZ14/O14 -> 0.49740375 | EC14: 46073 | ED14: =+DZ14*1.15 -> 596.8845 | EE14: CPM | EF14: =+EG14/DX14 -> 0.075341627 | EG14: =+EP14 -> 1572347 | EH14: =IFERROR((+DZ14/EG14*1000),"") -> 0.33009889 | EI14: =IFERROR(+DZ14/EO14,"") -> 0.036768915 | EJ14: =+IFERROR(+DZ14/EN14,"") -> 0.5123692 | EK14: =IFERROR(+(+DZ14/EP14*1000),"") -> 0.33009889 | EL14: 91085 | EM14: 17.26 | EN14: 1013 | EO14: 14116 | EP14: 1572347 | EQ14: =+IFERROR(+EN14/EP14,"") -> 0.00064425982 | ER14: =IFERROR(+EO14/EP14,"") -> 0.0089776621 | ES14: JOB:DCEEA5A10068_MKT:MKT0022145_MARCA:DC_PLATAFORMA:META_FECHA:25012026_CAMPAÑA:VACCOSTA2026_ETAPA:LAYER01_COMPRA:CPM_COMUNICACION:LANZAMIENTO_FORMATO:VIDEOADREEL_AUDIENCIA:BASESOCIOS | ET14: PAUSADO | EU14: PAUSADO EL 11 FEB PARA MOVER PPTO A YOUTUBE | EV14: https://www.dinersclub.com.ec/blubenefits/?utm_source=META&utm_medium=CPM&utm_campaign=DINERS-VACCOSTA-2026-MKT0022145&utm_id=DINERS-VACCOSTA-2026-MKT0022145&utm_term=DINERS-VACCOSTA-2026-MKT0022145&utm_content=META-VIDEOADREEL
H15: RMK WEB/RMK INTERACCIÓN RRSS REGION COSTA | I15: 155000 | K15: =+N15/$N$84 -> 0.022926115 | L15: =+N15 -> 700 | N15: 700 | O15: =+N15/1.15 -> 608.69565 | P15: 122.63 | R15: 700 | AB15: =+N15*60% -> 420 | AI15: =+N15*40% -> 280 | DW15: 0.05 | DX15: =O15/DW15*1000 -> 12173913 | DZ15: 303.64 | EA15: =+O15-DZ15 -> 305.05565 | EB15: =+DZ15/O15 -> 0.49883714 | EC15: 46073 | ED15: =+DZ15*1.15 -> 349.186 | EE15: CPM | EF15: =+EG15/DX15 -> 0.11220542 | EG15: =+EP15 -> 1365979 | EH15: =IFERROR((+DZ15/EG15*1000),"") -> 0.22228746 | EI15: =IFERROR(+DZ15/EO15,"") -> 0.039098635 | EJ15: =+IFERROR(+DZ15/EN15,"") -> 0.54611511 | EK15: =IFERROR(+(+DZ15/EP15*1000),"") -> 0.22228746 | EL15: 276131 | EM15: 4.95 | EN15: 556 | EO15: 7766 | EP15: 1365979 | EQ15: =+IFERROR(+EN15/EP15,"") -> 0.00040703408 | ER15: =IFERROR(+EO15/EP15,"") -> 0.0056852997 | ES15: JOB:DCEEA5A10068_MKT:MKT0022145_MARCA:DC_PLATAFORMA:META_FECHA:25012026_CAMPAÑA:VACCOSTA2026_ETAPA:LAYER01_COMPRA:CPM_COMUNICACION:LANZAMIENTO_FORMATO:VIDEOADREEL_AUDIENCIA:RMK | ET15: PAUSADO | EV15: https://www.dinersclub.com.ec/blubenefits/?utm_source=META&utm_medium=CPM&utm_campaign=DINERS-VACCOSTA-2026-MKT0022145&utm_id=DINERS-VACCOSTA-2026-MKT0022145&utm_term=DINERS-VACCOSTA-2026-MKT0022145&utm_content=META-VIDEOADREEL | EX15: NUEVO PPTO
E16: TIKTOK | F16: SPARK AD | H16: BASE SOCIOS DINERS REGION COSTA | I16: 114500 | J16: CPM | K16: =+N16/$N$84 -> 0.0098254778 | L16: =+N16 -> 300 | N16: 300 | O16: =+N16/1.05 -> 285.71429 | P16: 71.97 | R16: 900 | AB16: =+N16*60% -> 180 | AI16: =+N16*40% -> 120 | DW16: 0.89 | DX16: =O16/DW16*1000 -> 321027.29 | DZ16: 199.38 | EA16: =+O16-DZ16 -> 86.334286 | EB16: =+DZ16/O16 -> 0.69783 | EC16: 46083 | ED16: =+DZ16*1.15 -> 229.287 | EE16: CPM | EF16: =+EG16/DX16 -> 1.8454226 | EG16: =+EP16 -> 592431 | EH16: =IFERROR((+DZ16/EG16*1000),"") -> 0.33654552 | EI16: =IFERROR(+DZ16/EO16,"") -> 0.043896962 | EJ16: =+IFERROR(+DZ16/EN16,"") -> 0.16939677 | EK16: =IFERROR(+(+DZ16/EP16*1000),"") -> 0.33654552 | EL16: 92344 | EM16: 6.42 | EN16: 1177 | EO16: 4542 | EP16: 592431 | EQ16: =+IFERROR(+EN16/EP16,"") -> 0.0019867293 | ER16: =IFERROR(+EO16/EP16,"") -> 0.0076667156 | ES16: JOB:DCEEA5A10068_MKT:MKT0022145_MARCA:DC_PLATAFORMA:TIKTOK_FECHA:25012026_CAMPAÑA:VACCOSTA2026_ETAPA:LAYER01_COMPRA:CPM_COMUNICACION:LANZAMIENTO_FORMATO:SPARKAD_AUDIENCIA:BASESOCIOS | ET16: EN PAUTA | EU16: Se duplico el 24 de feb, por que se desactivaron todas las campañas de TikTok. | EV16: https://www.dinersclub.com.ec/blubenefits/?utm_source=TIKTOK&utm_medium=CPM&utm_campaign=DINERS-VACCOSTA-2026-MKT0022145&utm_id=DINERS-VACCOSTA-2026-MKT0022145&utm_term=DINERS-VACCOSTA-2026-MKT0022145&utm_content=TIKTOK-SPARKAD | EW16: 177.69 | EX16: =O16-EW16 -> 108.02429
H17: RMK WEB REGION COSTA | I17: =1640645*24.8% -> 406879.96 | K17: =+N17/$N$84 -> 0.0098254778 | L17: =+N17 -> 300 | N17: 300 | O17: =+N17/1.05 -> 285.71429 | P17: 65.73 | R17: 300 | AB17: =+N17*60% -> 180 | AI17: =+N17*40% -> 120 | DW17: 0.89 | DX17: =O17/DW17*1000 -> 321027.29 | DZ17: 208.92 | EA17: =+O17-DZ17 -> 76.794286 | EB17: =+DZ17/O17 -> 0.73122 | EC17: 46079 | ED17: =+DZ17*1.15 -> 240.258 | EE17: CPM | EF17: =+EG17/DX17 -> 2.5169574 | EG17: =+EP17 -> 808012 | EH17: =IFERROR((+DZ17/EG17*1000),"") -> 0.25856052 | EI17: =IFERROR(+DZ17/EO17,"") -> 0.046211015 | EJ17: =+IFERROR(+DZ17/EN17,"") -> 0.12631197 | EK17: =IFERROR(+(+DZ17/EP17*1000),"") -> 0.25856052 | EL17: 210164 | EM17: 3.84 | EN17: 1654 | EO17: 4521 | EP17: 808012 | EQ17: =+IFERROR(+EN17/EP17,"") -> 0.0020469993 | ER17: =IFERROR(+EO17/EP17,"") -> 0.0055952139 | ES17: JOB:DCEEA5A10068_MKT:MKT0022145_MARCA:DC_PLATAFORMA:TIKTOK_FECHA:25012026_CAMPAÑA:VACCOSTA2026_ETAPA:LAYER01_COMPRA:CPM_COMUNICACION:LANZAMIENTO_FORMATO:SPARKAD_AUDIENCIA:RMK | ET17: EN PAUTA | EV17: https://www.dinersclub.com.ec/blubenefits/?utm_source=TIKTOK&utm_medium=CPM&utm_campaign=DINERS-VACCOSTA-2026-MKT0022145&utm_id=DINERS-VACCOSTA-2026-MKT0022145&utm_term=DINERS-VACCOSTA-2026-MKT0022145&utm_content=TIKTOK-SPARKAD | EW17: 155.68 | EX17: =O17-EW17 -> 130.03429
E18: YOUTUBE | F18: INSTREAM | H18: BASE SOCIOS DINERS REGION COSTA | I18: 54000 | J18: CPM | K18: =+N18/$N$84 -> 0.01604828 | L18: =+N18 -> 490 | N18: =700*70% -> 490 | O18: =+N18/1.05 -> 466.66667 | P18: 74.75 | R18: 490 | AB18: =+N18*60% -> 294 | AI18: =+N18*40% -> 196 | DW18: 1 | DX18: =O18/DW18*1000 -> 466666.67 | DZ18: 438.47 | EA18: =+O18-DZ18 -> 28.196667 | EB18: =+DZ18/O18 -> 0.93957857 | EC18: 46079 | ED18: =+DZ18*1.15 -> 504.2405 | EE18: CPM | EF18: =+EG18/DX18 -> 0.99748714 | EG18: =+EP18 -> 465494 | EH18: =IFERROR((+DZ18/EG18*1000),"") -> 0.94194555 | EI18: =IFERROR(+DZ18/EO18,"") -> 0.003857021 | EJ18: =+IFERROR(+DZ18/EN18,"") -> 0.23335285 | EK18: =IFERROR(+(+DZ18/EP18*1000),"") -> 0.94194555 | EN18: 1879 | EO18: 113681 | EP18: 465494 | EQ18: =+IFERROR(+EN18/EP18,"") -> 0.0040365719 | ER18: =IFERROR(+EO18/EP18,"") -> 0.24421582 | ES18: JOB:DCEEA5A10068_MKT:MKT0022145_MARCA:DC_PLATAFORMA:YOUTUBE_FECHA:26012026_CAMPAÑA:VACCOSTA2026_ETAPA:LAYER01_COMPRA:CPM_COMUNICACION:LANZAMIENTO_FORMATO:INSTREAM_AUDIENCIA:BASESOCIOS | ET18: EN PAUTA | EU18: PPTO SE CAMBIO EL 11 FEB | EV18: www.dinersclub.com.ec/blubenefits/?utm_source=YOUTUBE&utm_medium=CPM&utm_campaign=DINERS-VACCOSTA-2026-MKT0022145&utm_id=DINERS-VACCOSTA-2026-MKT0022145&utm_term=DINERS-VACCOSTA-2026-MKT0022145&utm_content=YOUTUBE-INSTREAM
H19: RMK WEB REGION COSTA | I19: - | K19: =+N19/$N$84 -> 0.0068778345 | L19: =+N19 -> 210 | N19: =300*70% -> 210 | O19: =+N19/1.05 -> 200 | P19: 31.97 | R19: 210 | AB19: =+N19*60% -> 126 | AI19: =+N19*40% -> 84 | DW19: 1 | DX19: =O19/DW19*1000 -> 200000 | DZ19: 188.51 | EA19: =+O19-DZ19 -> 11.49 | EB19: =+DZ19/O19 -> 0.94255 | EC19: 46079 | ED19: =+DZ19*1.15 -> 216.7865 | EE19: CPM | EF19: =+EG19/DX19 -> 1.62426 | EG19: =+EP19 -> 324852 | EH19: =IFERROR((+DZ19/EG19*1000),"") -> 0.58029503 | EI19: =IFERROR(+DZ19/EO19,"") -> 0.002215419 | EJ19: =+IFERROR(+DZ19/EN19,"") -> 0.094633534 | EK19: =IFERROR(+(+DZ19/EP19*1000),"") -> 0.58029503 | EN19: 1992 | EO19: 85090 | EP19: 324852 | EQ19: =+IFERROR(+EN19/EP19,"") -> 0.0061320232 | ER19: =IFERROR(+EO19/EP19,"") -> 0.26193467 | ES19: JOB:DCEEA5A10068_MKT:MKT0022145_MARCA:DC_PLATAFORMA:YOUTUBE_FECHA:26012026_CAMPAÑA:VACCOSTA2026_ETAPA:LAYER01_COMPRA:CPM_COMUNICACION:LANZAMIENTO_FORMATO:INSTREAM_AUDIENCIA:RMK | ET19: EN PAUTA | EV19: www.dinersclub.com.ec/blubenefits/?utm_source=YOUTUBE&utm_medium=CPM&utm_campaign=DINERS-VACCOSTA-2026-MKT0022145&utm_id=DINERS-VACCOSTA-2026-MKT0022145&utm_term=DINERS-VACCOSTA-2026-MKT0022145&utm_content=YOUTUBE-INSTREAM
F20: SHORTS | H20: BASE SOCIOS DINERS REGION COSTA | I20: 54000 | J20: CPM | K20: =+N20/$N$84 -> 0.0068778345 | L20: =+N20 -> 210 | N20: =700*30% -> 210 | O20: =+N20/1.05 -> 200 | P20: 30.19 | R20: 210 | AB20: =+N20*60% -> 126 | AI20: =+N20*40% -> 84 | DW20: 1 | DX20: =O20/DW20*1000 -> 200000 | DZ20: 188.01 | EA20: =+O20-DZ20 -> 11.99 | EB20: =+DZ20/O20 -> 0.94005 | EC20: 46079 | ED20: =+DZ20*1.15 -> 216.2115 | EE20: CPM | EF20: =+EG20/DX20 -> 1.052645 | EG20: =+EP20 -> 210529 | EH20: =IFERROR((+DZ20/EG20*1000),"") -> 0.89303611 | EI20: =IFERROR(+DZ20/EO20,"") -> 0.038004851 | EJ20: =+IFERROR(+DZ20/EN20,"") -> 1.0930814 | EK20: =IFERROR(+(+DZ20/EP20*1000),"") -> 0.89303611 | EN20: 172 | EO20: 4947 | EP20: 210529 | EQ20: =+IFERROR(+EN20/EP20,"") -> 0.00081698958 | ER20: =IFERROR(+EO20/EP20,"") -> 0.02349795 | ES20: JOB:DCEEA5A10068_MKT:MKT0022145_MARCA:DC_PLATAFORMA:YOUTUBE_FECHA:26012026_CAMPAÑA:VACCOSTA2026_ETAPA:LAYER01_COMPRA:CPM_COMUNICACION:LANZAMIENTO_FORMATO:SHORTS_AUDIENCIA:BASESOCIOS | ET20: EN PAUTA | EV20: https://www.dinersclub.com.ec/blubenefits/?utm_source=YOUTUBE&utm_medium=CPM&utm_campaign=DINERS-VACCOSTA-2026-MKT0022145&utm_id=DINERS-VACCOSTA-2026-MKT0022145&utm_term=DINERS-VACCOSTA-2026-MKT0022145&utm_content=YOUTUBE-SHORTS
H21: RMK WEB REGION COSTA | I21: - | K21: =+N21/$N$84 -> 0.0029476433 | L21: =+N21 -> 90 | N21: =300*30% -> 90 | O21: =+N21/1.05 -> 85.714286 | P21: 13.57 | R21: 90 | AB21: =+N21*60% -> 54 | AI21: =+N21*40% -> 36 | DW21: 1 | DX21: =O21/DW21*1000 -> 85714.286 | DZ21: 80.04 | EA21: =+O21-DZ21 -> 5.6742857 | EB21: =+DZ21/O21 -> 0.9338 | EC21: 46079 | ED21: =+DZ21*1.15 -> 92.046 | EE21: CPM | EF21: =+EG21/DX21 -> 2.0728633 | EG21: =+EP21 -> 177674 | EH21: =IFERROR((+DZ21/EG21*1000),"") -> 0.45048797 | EI21: =IFERROR(+DZ21/EO21,"") -> 0.014918919 | EJ21: =+IFERROR(+DZ21/EN21,"") -> 0.23267442 | EK21: =IFERROR(+(+DZ21/EP21*1000),"") -> 0.45048797 | EN21: 344 | EO21: 5365 | EP21: 177674 | EQ21: =+IFERROR(+EN21/EP21,"") -> 0.0019361302 | ER21: =IFERROR(+EO21/EP21,"") -> 0.030195752 | ES21: JOB:DCEEA5A10068_MKT:MKT0022145_MARCA:DC_PLATAFORMA:YOUTUBE_FECHA:26012026_CAMPAÑA:VACCOSTA2026_ETAPA:LAYER01_COMPRA:CPM_COMUNICACION:LANZAMIENTO_FORMATO:SHORTS_AUDIENCIA:RMK | ET21: EN PAUTA | EV21: https://www.dinersclub.com.ec/blubenefits/?utm_source=YOUTUBE&utm_medium=CPM&utm_campaign=DINERS-VACCOSTA-2026-MKT0022145&utm_id=DINERS-VACCOSTA-2026-MKT0022145&utm_term=DINERS-VACCOSTA-2026-MKT0022145&utm_content=YOUTUBE-SHORTS
E22: DV360 | F22: INSTREAM CONTEXTUAL NATIVE ADS | H22: INTERESES; VIAJES, AGENCIA DE VIAJES, EXPERIENCIAS, COMPRAS EN EL EXTERIOR, TURISMO, HOTELES APP TARGETING AIRBNB/BOOKING/KAYAC/TRIP ADVISOR/DESPEGAR/LATAM AIRLINES/WAZE/TRIPPY/ECUADOR TRAVEL | I22: - | J22: CPM | K22: =+N22/$N$84 -> 0.13100637 | L22: =+N22 -> 4000 | N22: 4000 | O22: =+N22/1.05 -> 3809.5238 | P22: 800.37 | R22: 4000 | AB22: =+N22*60% -> 2400 | AI22: =+N22*40% -> 1600 | DW22: 1 | DX22: =O22/DW22*1000 -> 3809523.8 | DZ22: 208.68 | EA22: =+O22-DZ22 -> 3600.8438 | EB22: =+DZ22/O22 -> 0.0547785 | EC22: 46072 | ED22: =+DZ22*1.15 -> 239.982 | EE22: CPM | EF22: =+EG22/DX22 -> 1.0399848 | EG22: =+EP22 -> 3961847 | EH22: =IFERROR((+DZ22/EG22*1000),"") -> 0.052672403 | EI22: =IFERROR(+DZ22/EO22,"") | EJ22: =+IFERROR(+DZ22/EN22,"") | EK22: =IFERROR(+(+DZ22/EP22*1000),"") -> 0.052672403 | EP22: 3961847 | EQ22: =+IFERROR(+EN22/EP22,"") -> 0 | ER22: =IFERROR(+EO22/EP22,"") -> 0 | ES22: JOB:DCEEA5A10068_MKT:MKT0022145_MARCA:DC_PLATAFORMA:DV360_FECHA:27012026_CAMPAÑA:VACCOSTA2026_ETAPA:LAYER01_COMPRA:CPM_COMUNICACION:LANZAMIENTO_FORMATO:INSTREAM_AUDIENCIA:INTERESESVIAJES | ET22: FINALIZADO | EU22: SE PAUSÓ EL 20 DE FEB | EV22: https://www.dinersclub.com.ec/blubenefits/?utm_source=DV360&utm_medium=CPM&utm_campaign=DINERS-VACCOSTA-2026-MKT0022145&utm_id=DINERS-VACCOSTA-2026-MKT0022145&utm_term=DINERS-VACCOSTA-2026-MKT0022145&utm_content=DV360
C23: LAYER 01 | L23: =SUM(L14:L22) -> 7500 | M23: =SUM(M14:M22) -> 0 | N23: =SUM(N14:N22) -> 7500 | O23: =SUM(O14:O22) -> 6985.5072 | R23: =SUM(R14:R22) -> 8100
C24: LAYER 02 CONSIDERACIÓN IDENTIFICACIÓN | D24: AEROLINEAS | E24: META | F24: REEL/VIDEO AD | G24: ESPECIALIDADES AEROLINEAS Snackables convisualizaciones de experiencias unicas en vuelos y beneficios ser socio. | H24: BASE SOCIOS DINERS (EXC RMK VISUALIZACIÓN AEROLINEAS) REGION COSTA | I24: 266000 | J24: CPV TRUVIEW 2 SEG | K24: =+N24/$N$84 -> 0.027699111 | L24: =+N24 -> 845.73324 | N24: =745.73324+100 -> 845.73324 | O24: =+N24/1.15 -> 735.42021 | P24: 89.85 | R24: 745.73324 | S24: =R24/1.15 -> 648.46369 | AD24: =+O24*20% -> 147.08404 | AI24: =+O24*50% -> 367.7101 | BK24: =+O24*30% -> 220.62606 | DW24: 0.09 | DX24: =O24/DW24 -> 8171.3357 | DZ24: 609.61 | EA24: =+O24-DZ24 -> 125.81021 | EB24: =+DZ24/O24 -> 0.82892745 | EC24: 46079 | ED24: =+DZ24*1.15 -> 701.0515 | EE24: CPV | EF24: =+EG24/DX24 -> 0.95259824 | EG24: =+EO24 -> 7784 | EH24: =IFERROR((+DZ24/EG24*1000),"") -> 78.315776 | EI24: =IFERROR(+DZ24/EO24,"") -> 0.078315776 | EJ24: =+IFERROR(+DZ24/EN24,"") -> 2.3812891 | EK24: =IFERROR(+(+DZ24/EP24*1000),"") -> 0.97893777 | EL24: 87429 | EM24: 7.12 | EN24: 256 | EO24: 7784 | EP24: 622726 | EQ24: =+IFERROR(+EN24/EP24,"") -> 0.00041109573 | ER24: =IFERROR(+EO24/EP24,"") -> 0.01249988 | ES24: JOB:DCEEA5A10068_MKT:MKT0022145_MARCA:DC_PLATAFORMA:META_FECHA:27012026_CAMPAÑA:VACCOSTA2026_ETAPA:LAYER02_COMPRA:CPV_COMUNICACION:AEROLINEAS_FORMATO:VIDEOADREEL_AUDIENCIA:BASESOCIOS | ET24: EN PAUTA | EU24: se aumento el creativo de tiktok el 11 de feb | EV24: https://www.dinersclub.com.ec/blubenefits/?utm_source=META&utm_medium=CPV&utm_campaign=DINERS-VACCOSTA-2026-MKT0022145&utm_id=DINERS-VACCOSTA-2026-MKT0022145&utm_term=DINERS-VACCOSTA-2026-MKT0022145&utm_content=META-VIDEOADREEL | EW24: *el 27 de feb se cambiaron todos los pptos y se exc base de views de toda la LAYER 02
H25: RMK WEB/RMK INTERACCIÓN RRSS (EXC RMK VISUALIZACIÓN AEROLINEAS) REGION COSTA | I25: 155000 | K25: =+N25/$N$84 -> 0.026810449 | L25: =+N25 -> 818.59986 | N25: =1118.59986-400+100 -> 818.59986 | O25: =+N25/1.15 -> 711.82597 | P25: 87.66 | R25: 718.59986 | S25: =R25/1.15 -> 624.86944 | AD25: =+O25*20% -> 142.36519 | AI25: =+O25*50% -> 355.91298 | BK25: =+O25*30% -> 213.54779 | DW25: 0.09 | DX25: =O25/DW25 -> 7909.1774 | DZ25: 586.15 | EA25: =+O25-DZ25 -> 125.67597 | EB25: =+DZ25/O25 -> 0.82344566 | EC25: 46079 | ED25: =+DZ25*1.15 -> 674.0725 | EE25: CPV | EF25: =+EG25/DX25 -> 2.5366734 | EG25: =+EO25 -> 20063 | EH25: =IFERROR((+DZ25/EG25*1000),"") -> 29.215471 | EI25: =IFERROR(+DZ25/EO25,"") -> 0.029215471 | EJ25: =+IFERROR(+DZ25/EN25,"") -> 1.5630667 | EK25: =IFERROR(+(+DZ25/EP25*1000),"") -> 0.52520048 | EL25: 184390 | EM25: 6.05 | EN25: 375 | EO25: 20063 | EP25: 1116050 | EQ25: =+IFERROR(+EN25/EP25,"") -> 0.00033600645 | ER25: =IFERROR(+EO25/EP25,"") -> 0.017976793 | ES25: JOB:DCEEA5A10068_MKT:MKT0022145_MARCA:DC_PLATAFORMA:META_FECHA:27012026_CAMPAÑA:VACCOSTA2026_ETAPA:LAYER02_COMPRA:CPV_COMUNICACION:AEROLINEAS_FORMATO:VIDEOADREEL_AUDIENCIA:RMK | ET25: EN PAUTA | EV25: https://www.dinersclub.com.ec/blubenefits/?utm_source=META&utm_medium=CPV&utm_campaign=DINERS-VACCOSTA-2026-MKT0022145&utm_id=DINERS-VACCOSTA-2026-MKT0022145&utm_term=DINERS-VACCOSTA-2026-MKT0022145&utm_content=META-VIDEOADREEL
E26: META | F26: DINAMICOS | G26: ESPECIALIDADES AEROLINEAS Snackables convisualizaciones de experiencias unicas en vuelos y beneficios ser socio. | H26: BASE SOCIOS DINERS (EXC RMK VISUALIZACIÓN AEROLINEAS) REGION COSTA | I26: 266000 | J26: CPC | K26: =+N26/$N$84 -> 0.016319899 | L26: =+N26 -> 498.2933 | N26: =398.293296+100 -> 498.2933 | O26: =+N26/1.15 -> 433.29852 | P26: 47.02 | R26: 398.2933 | S26: =R26/1.15 -> 346.342 | AD26: =+O26*20% -> 86.659704 | AI26: =+O26*50% -> 216.64926 | BK26: =+O26*30% -> 129.98956 | DW26: 0.09 | DX26: =O26/DW26 -> 4814.428 | DZ26: 291.04 | EA26: =+O26-DZ26 -> 142.25852 | EB26: =+DZ26/O26 -> 0.67168473 | EC26: 46079 | ED26: =+DZ26*1.15 -> 334.696 | EE26: CPC | EF26: =+EG26/DX26 -> 0.49247803 | EG26: =+EN26 -> 2371 | EH26: =IFERROR((+DZ26/EG26*1000),"") -> 122.74989 | EI26: =IFERROR(+DZ26/EO26,"") | EJ26: =+IFERROR(+DZ26/EN26,"") -> 0.12274989 | EK26: =IFERROR(+(+DZ26/EP26*1000),"") -> 1.2694646 | EL26: 46518 | EM26: 4.93 | EN26: 2371 | EO26: - | EP26: 229262 | EQ26: =+IFERROR(+EN26/EP26,"") -> 0.01034188 | ER26: =IFERROR(+EO26/EP26,"") | ES26: JOB:DCEEA5A10068_MKT:MKT0022145_MARCA:DC_PLATAFORMA:META_FECHA:27012026_CAMPAÑA:VACCOSTA2026_ETAPA:LAYER02_COMPRA:CPC_COMUNICACION:AEROLINEAS_FORMATO:DINAMICOS_AUDIENCIA:BASESOCIOS | ET26: EN PAUTA | EU26: se rechazaron los anuncios, se volvió a activar el 23 de feb | EV26: https://www.dinersclub.com.ec/blubenefits/?utm_source=META&utm_medium=CPC&utm_campaign=DINERS-VACCOSTA-2026-MKT0022145&utm_id=DINERS-VACCOSTA-2026-MKT0022145&utm_term=DINERS-VACCOSTA-2026-MKT0022145&utm_content=META-DINAMICOS
H27: RMK WEB/RMK INTERACCIÓN RRSS (EXC RMK VISUALIZACIÓN AEROLINEAS) REGION COSTA | I27: 155000 | K27: =+N27/$N$84 -> 0.011379212 | L27: =+N27 -> 347.43994 | N27: =247.439944+100 -> 347.43994 | O27: =+N27/1.15 -> 302.12169 | P27: 29.93 | R27: 247.43994 | S27: =R27/1.15 -> 215.16517 | AD27: =+O27*20% -> 60.424338 | AI27: =+O27*50% -> 151.06085 | BK27: =+O27*30% -> 90.636507 | DW27: 0.09 | DX27: =O27/DW27 -> 3356.9077 | DZ27: 180.68 | EA27: =+O27-DZ27 -> 121.44169 | EB27: =+DZ27/O27 -> 0.59803717 | EC27: 46079 | ED27: =+DZ27*1.15 -> 207.782 | EE27: CPC | EF27: =+EG27/DX27 -> 1.0354768 | EG27: =+EN27 -> 3476 | EH27: =IFERROR((+DZ27/EG27*1000),"") -> 51.979287 | EI27: =IFERROR(+DZ27/EO27,"") | EJ27: =+IFERROR(+DZ27/EN27,"") -> 0.051979287 | EK27: =IFERROR(+(+DZ27/EP27*1000),"") -> 0.85862282 | EL27: 76848 | EM27: 2.74 | EN27: 3476 | EO27: - | EP27: 210430 | EQ27: =+IFERROR(+EN27/EP27,"") -> 0.016518557 | ER27: =IFERROR(+EO27/EP27,"") | ES27: JOB:DCEEA5A10068_MKT:MKT0022145_MARCA:DC_PLATAFORMA:META_FECHA:27012026_CAMPAÑA:VACCOSTA2026_ETAPA:LAYER02_COMPRA:CPC_COMUNICACION:AEROLINEAS_FORMATO:DINAMICO_AUDIENCIA:RMK | ET27: EN PAUTA | EV27: https://www.dinersclub.com.ec/blubenefits/?utm_source=META&utm_medium=CPC&utm_campaign=DINERS-VACCOSTA-2026-MKT0022145&utm_id=DINERS-VACCOSTA-2026-MKT0022145&utm_term=DINERS-VACCOSTA-2026-MKT0022145&utm_content=META-DINAMICOS | EX27: NUEVO PPTO
E28: TIKTOK | F28: INFEED | G28: ESPECIALIDADES AEROLINEAS Snackables convisualizaciones de experiencias unicas en vuelos y beneficios ser socio. | H28: BASE SOCIOS DINERS (EXC RMK VISUALIZACIÓN AEROLINEAS) REGION COSTA | I28: 109000 | J28: CPV | K28: =+N28/$N$84 -> 0.014682319 | L28: =+N28 -> 448.2933 | N28: =298.293296+100+50 -> 448.2933 | O28: =+N28/1.05 -> 426.946 | P28: 45.07 | R28: 298.2933 | S28: =R28/1.05 -> 284.08885 | AD28: =+O28*20% -> 85.389199 | AI28: =+O28*50% -> 213.473 | BK28: =+O28*30% -> 128.0838 | DW28: 0.1 | DX28: =O28/DW28 -> 4269.46 | DZ28: 234.2 | EA28: =+O28-DZ28 -> 192.746 | EB28: =+DZ28/O28 -> 0.54854713 | EC28: 46079 | ED28: =+DZ28*1.15 -> 269.33 | EE28: CPV | EF28: =+EG28/DX28 -> 2.3953849 | EG28: =+EO28 -> 10227 | EH28: =IFERROR((+DZ28/EG28*1000),"") -> 22.900166 | EI28: =IFERROR(+DZ28/EO28,"") -> 0.022900166 | EJ28: =+IFERROR(+DZ28/EN28,"") -> 0.2964557 | EK28: =IFERROR(+(+DZ28/EP28*1000),"") -> 0.89919909 | EL28: 66986 | EM28: 3.89 | EN28: 790 | EO28: 10227 | EP28: 260454 | EQ28: =+IFERROR(+EN28/EP28,"") -> 0.0030331652 | ER28: =IFERROR(+EO28/EP28,"") -> 0.039266051 | ES28: JOB:DCEEA5A10068_MKT:MKT0022145_MARCA:DC_PLATAFORMA:TIKTOK_FECHA:27012026_CAMPAÑA:VACCOSTA2026_ETAPA:LAYER02_COMPRA:CPV_COMUNICACION:AEROLINEAS_FORMATO:INFEED_AUDIENCIA:BASESOCIOS | ET28: EN PAUTA | EU28: Se duplico el 24 de feb, por que se desactivaron todas las campañas de TikTok. | EV28: https://www.dinersclub.com.ec/blubenefits/?utm_source=TIKTOK&utm_medium=CPV&utm_campaign=DINERS-VACCOSTA-2026-MKT0022145&utm_id=DINERS-VACCOSTA-2026-MKT0022145&utm_term=DINERS-VACCOSTA-2026-MKT0022145&utm_content=TIKTOK-INFEED | EW28: 150.89 | EX28: =O28-EW28 -> 276.056
H29: RMK WEB/RMK INTERACCIÓN RRSS (EXC RMK VISUALIZACIÓN AEROLINEAS) REGION COSTA | I29: 155000 | K29: =+N29/$N$84 -> 0.01629195 | L29: =+N29 -> 497.43994 | N29: =347.439944+100+50 -> 497.43994 | O29: =+N29/1.05 -> 473.75233 | P29: 53.32 | R29: 347.43994 | S29: =R29/1.05 -> 330.89518 | AD29: =+O29*20% -> 94.750466 | AI29: =+O29*50% -> 236.87616 | BK29: =+O29*30% -> 142.1257 | DW29: 0.1 | DX29: =O29/DW29 -> 4737.5233 | DZ29: 265.07 | EA29: =+O29-DZ29 -> 208.68233 | EB29: =+DZ29/O29 -> 0.55951176 | EC29: 46079 | ED29: =+DZ29*1.15 -> 304.8305 | EE29: CPV | EF29: =+EG29/DX29 -> 4.3134353 | EG29: =+EO29 -> 20435 | EH29: =IFERROR((+DZ29/EG29*1000),"") -> 12.971373 | EI29: =IFERROR(+DZ29/EO29,"") -> 0.012971373 | EJ29: =+IFERROR(+DZ29/EN29,"") -> 0.14758909 | EK29: =IFERROR(+(+DZ29/EP29*1000),"") -> 0.69392414 | EL29: 127921 | EM29: 2.99 | EN29: 1796 | EO29: 20435 | EP29: 381987 | EQ29: =+IFERROR(+EN29/EP29,"") -> 0.0047017307 | ER29: =IFERROR(+EO29/EP29,"") -> 0.053496585 | ES29: JOB:DCEEA5A10068_MKT:MKT0022145_MARCA:DC_PLATAFORMA:TIKTOK_FECHA:27012026_CAMPAÑA:VACCOSTA2026_ETAPA:LAYER02_COMPRA:CPV_COMUNICACION:AEROLINEAS_FORMATO:INFEED_AUDIENCIA:RMK | ET29: EN PAUTA | EV29: https://www.dinersclub.com.ec/blubenefits/?utm_source=TIKTOK&utm_medium=CPV&utm_campaign=DINERS-VACCOSTA-2026-MKT0022145&utm_id=DINERS-VACCOSTA-2026-MKT0022145&utm_term=DINERS-VACCOSTA-2026-MKT0022145&utm_content=TIKTOK-INFEED | EW29: 172.09 | EX29: =O29-EW29 -> 301.66233
E30: YOUTUBE | F30: INSTREAM | G30: ESPECIALIDADES AEROLINEAS Snackables convisualizaciones de experiencias unicas en vuelos y beneficios ser socio. | H30: BASE SOCIOS DINERS (EXC RMK VISUALIZACIÓN AEROLINEAS) REGION COSTA | I30: 54000 | J30: CPV | K30: =+N30/$N$84 -> 0.0035765898 | L30: =+N30 -> 109.20354 | N30: =(198.862197333209*70%)-30 -> 109.20354 | O30: =+N30/1.05 -> 104.00337 | R30: 139.20354 | S30: =R30/1.05 -> 132.5748 | AD30: =+O30*20% -> 20.800674 | AI30: =+O30*50% -> 52.001685 | BK30: =+O30*30% -> 31.201011 | DW30: 1 | DX30: =O30/DW30 -> 104.00337 | EA30: =+O30-DZ30 -> 104.00337 | EB30: =+DZ30/O30 -> 0 | ED30: =+DZ30*1.15 -> 0 | EE30: CPV | EF30: =+EG30/DX30 -> 0 | EG30: =+EP30 -> 0 | EH30: =IFERROR((+DZ30/EG30*1000),"") | EI30: =IFERROR(+DZ30/EO30,"") | EJ30: =+IFERROR(+DZ30/EN30,"") | EK30: =IFERROR(+(+DZ30/EP30*1000),"") | EQ30: =+IFERROR(+EN30/EP30,"") | ER30: =IFERROR(+EO30/EP30,"") | ES30: JOB:DCEEA5A10068_MKT:MKT0022145_MARCA:DC_PLATAFORMA:YOUTUBE_FECHA:27022026_CAMPAÑA:VACCOSTA2026_ETAPA:LAYER02_COMPRA:CPV_COMUNICACION:AEROLINEAS_FORMATO:INSTREAM_AUDIENCIA:BASESOCIOS | ET30: EN PAUTA | EV30: www.dinersclub.com.ec/blubenefits/?utm_source=YOUTUBE&utm_medium=CPV&utm_campaign=DINERS-VACCOSTA-2026-MKT0022145&utm_id=DINERS-VACCOSTA-2026-MKT0022145&utm_term=DINERS-VACCOSTA-2026-MKT0022145&utm_content=YOUTUBE-INSTREAM
H31: RMK WEB/RMK INTERACCIÓN RRSS (EXC RMK VISUALIZACIÓN AEROLINEAS) REGION COSTA | I31: - | K31: =+N31/$N$84 -> 0.0035635471 | L31: =+N31 -> 108.80531 | N31: =(298.293295999814*70%)-100 -> 108.80531 | O31: =+N31/1.05 -> 103.6241 | R31: 208.80531 | S31: =R31/1.05 -> 198.8622 | AD31: =+O31*20% -> 20.72482 | AI31: =+O31*50% -> 51.812051 | BK31: =+O31*30% -> 31.087231 | DW31: 1 | DX31: =O31/DW31 -> 103.6241 | EA31: =+O31-DZ31 -> 103.6241 | EB31: =+DZ31/O31 -> 0 | ED31: =+DZ31*1.15 -> 0 | EE31: CPV | EF31: =+EG31/DX31 -> 0 | EG31: =+EP31 -> 0 | EH31: =IFERROR((+DZ31/EG31*1000),"") | EI31: =IFERROR(+DZ31/EO31,"") | EJ31: =+IFERROR(+DZ31/EN31,"") | EK31: =IFERROR(+(+DZ31/EP31*1000),"") | EQ31: =+IFERROR(+EN31/EP31,"") | ER31: =IFERROR(+EO31/EP31,"") | ES31: JOB:DCEEA5A10068_MKT:MKT0022145_MARCA:DC_PLATAFORMA:YOUTUBE_FECHA:27022026_CAMPAÑA:VACCOSTA2026_ETAPA:LAYER02_COMPRA:CPV_COMUNICACION:AEROLINEAS_FORMATO:INSTREAM_AUDIENCIA:RMK | ET31: EN PAUTA | EV31: www.dinersclub.com.ec/blubenefits/?utm_source=YOUTUBE&utm_medium=CPV&utm_campaign=DINERS-VACCOSTA-2026-MKT0022145&utm_id=DINERS-VACCOSTA-2026-MKT0022145&utm_term=DINERS-VACCOSTA-2026-MKT0022145&utm_content=YOUTUBE-INSTREAM
D32: HOTELES | E32: META | F32: REEL/VIDEO AD | G32: ESPECIALIDADES HOTELES Snackables con EXPERIENCIAS de amenities y beneficios | H32: BASE SOCIOS DINERS (EXC RMK VISUALIZACIÓN HOTELES) REGION COSTA | I32: 266000 | J32: CPV TRUVIEW 2 SEG | K32: =+N32/$N$84 -> 0.027699111 | L32: =+N32 -> 845.73324 | N32: =745.73324+100 -> 845.73324 | O32: =+N32/1.15 -> 735.42021 | P32: 88.02 | R32: 745.73324 | S32: =R32/1.15 -> 648.46369 | AD32: =+O32*20% -> 147.08404 | AI32: =+O32*50% -> 367.7101 | BK32: =+O32*30% -> 220.62606 | DW32: 0.09 | DX32: =O32/DW32 -> 8171.3357 | DZ32: 609.8 | EA32: =+O32-DZ32 -> 125.62021 | EB32: =+DZ32/O32 -> 0.82918581 | EC32: 46079 | ED32: =+DZ32*1.15 -> 701.27 | EE32: CPV | EF32: =+EG32/DX32 -> 0.85077891 | EG32: =+EO32 -> 6952 | EH32: =IFERROR((+DZ32/EG32*1000),"") -> 87.715765 | EI32: =IFERROR(+DZ32/EO32,"") -> 0.087715765 | EJ32: =+IFERROR(+DZ32/EN32,"") -> 2.3453846 | EK32: =IFERROR(+(+DZ32/EP32*1000),"") -> 0.99853936 | EL32: 99605 | EM32: 5.49 | EN32: 260 | EO32: 6952 | EP32: 610692 | EQ32: =+IFERROR(+EN32/EP32,"") -> 0.00042574653 | ER32: =IFERROR(+EO32/EP32,"") -> 0.011383807 | ES32: JOB:DCEEA5A10068_MKT:MKT0022145_MARCA:DC_PLATAFORMA:META_FECHA:27012026_CAMPAÑA:VACCOSTA2026_ETAPA:LAYER02_COMPRA:CPV_COMUNICACION:HOTELES_FORMATO:VIDEOADREEL_AUDIENCIA:BASESOCIOS | ET32: EN PAUTA | EU32: se aumento el creativo de tiktok el 11 de feb | EV32: https://www.dinersclub.com.ec/blubenefits/?utm_source=META&utm_medium=CPV&utm_campaign=DINERS-VACCOSTA-2026-MKT0022145&utm_id=DINERS-VACCOSTA-2026-MKT0022145&utm_term=DINERS-VACCOSTA-2026-MKT0022145&utm_content=META-VIDEOADREEL
H33: RMK WEB/RMK INTERACCIÓN RRSS (EXC RMK VISUALIZACIÓN HOTELES) REGION COSTA | I33: 155000 | K33: =+N33/$N$84 -> 0.026810449 | L33: =+N33 -> 818.59986 | N33: =1118.59986-400+100 -> 818.59986 | O33: =+N33/1.15 -> 711.82597 | P33: 88.7 | R33: 718.59986 | S33: =R33/1.15 -> 624.86944 | AD33: =+O33*20% -> 142.36519 | AI33: =+O33*50% -> 355.91298 | BK33: =+O33*30% -> 213.54779 | DW33: 0.09 | DX33: =O33/DW33 -> 7909.1774 | DZ33: 586.61 | EA33: =+O33-DZ33 -> 125.21597 | EB33: =+DZ33/O33 -> 0.82409188 | EC33: 46079 | ED33: =+DZ33*1.15 -> 674.6015 | EE33: CPV | EF33: =+EG33/DX33 -> 2.5612019 | EG33: =+EO33 -> 20257 | EH33: =IFERROR((+DZ33/EG33*1000),"") -> 28.958385 | EI33: =IFERROR(+DZ33/EO33,"") -> 0.028958385 | EJ33: =+IFERROR(+DZ33/EN33,"") -> 1.3705841 | EK33: =IFERROR(+(+DZ33/EP33*1000),"") -> 0.46927937 | EL33: 233673 | EM33: 4.87 | EN33: 428 | EO33: 20257 | EP33: 1250023 | EQ33: =+IFERROR(+EN33/EP33,"") -> 0.0003423937 | ER33: =IFERROR(+EO33/EP33,"") -> 0.016205302 | ES33: JOB:DCEEA5A10068_MKT:MKT0022145_MARCA:DC_PLATAFORMA:META_FECHA:27012026_CAMPAÑA:VACCOSTA2026_ETAPA:LAYER02_COMPRA:CPV_COMUNICACION:HOTELES_FORMATO:VIDEOADREEL_AUDIENCIA:RMK | ET33: EN PAUTA | EU33: se aumento el creativo de tiktok el 11 de feb | EV33: https://www.dinersclub.com.ec/blubenefits/?utm_source=META&utm_medium=CPV&utm_campaign=DINERS-VACCOSTA-2026-MKT0022145&utm_id=DINERS-VACCOSTA-2026-MKT0022145&utm_term=DINERS-VACCOSTA-2026-MKT0022145&utm_content=META-VIDEOADREEL
E34: META | F34: DINAMICOS | G34: ESPECIALIDADES HOTELES Snackables con EXPERIENCIAS de amenities y beneficios | H34: BASE SOCIOS DINERS (EXC RMK VISUALIZACIÓN HOTELES) REGION COSTA | I34: 266000 | J34: CPC | K34: =+N34/$N$84 -> 0.0035915396 | L34: 120.2 | M34: =+N34-L34 -> -10.54 | N34: =59.66+50 -> 109.66 | O34: =+N34/1.15 -> 95.356522 | R34: 59.66 | S34: =R34/1.15 -> 51.878261 | AD34: =+O34*20% -> 19.071304 | AI34: =+O34*50% -> 47.678261 | BK34: =+O34*30% -> 28.606957 | DW34: 0.09 | DX34: =O34/DW34 -> 1059.5169 | EA34: =+O34-DZ34 -> 95.356522 | EB34: =+DZ34/O34 -> 0 | ED34: =+DZ34*1.15 -> 0 | EE34: CPC | EF34: =+EG34/DX34 -> 0 | EG34: =+EN34 -> 0 | EH34: =IFERROR((+DZ34/EG34*1000),"") | EI34: =IFERROR(+DZ34/EO34,"") | EJ34: =+IFERROR(+DZ34/EN34,"") | EK34: =IFERROR(+(+DZ34/EP34*1000),"") | EQ34: =+IFERROR(+EN34/EP34,"") | ER34: =IFERROR(+EO34/EP34,"") | ES34: JOB:DCEEA5A10068_MKT:MKT0022145_MARCA:DC_PLATAFORMA:META_FECHA:27022026_CAMPAÑA:VACCOSTA2026_ETAPA:LAYER02_COMPRA:CPC_COMUNICACION:HOTELES_FORMATO:DINAMICOS_AUDIENCIA:BASESOCIOS | ET34: EN PAUTA | EV34: https://www.dinersclub.com.ec/blubenefits/?utm_source=META&utm_medium=CPC&utm_campaign=DINERS-VACCOSTA-2026-MKT0022145&utm_id=DINERS-VACCOSTA-2026-MKT0022145&utm_term=DINERS-VACCOSTA-2026-MKT0022145&utm_content=META-DINAMICOS
H35: RMK WEB/RMK INTERACCIÓN RRSS (EXC RMK VISUALIZACIÓN HOTELES) REGION COSTA | I35: 155000 | K35: =+N35/$N$84 -> 0.0045685197 | M35: =+N35 -> 139.49 | N35: =89.49+50 -> 139.49 | O35: =+N35/1.15 -> 121.29565 | R35: 89.49 | S35: =R35/1.15 -> 77.817391 | AD35: =+O35*20% -> 24.25913 | AI35: =+O35*50% -> 60.647826 | BK35: =+O35*30% -> 36.388696 | DW35: 0.09 | DX35: =O35/DW35 -> 1347.7295 | EA35: =+O35-DZ35 -> 121.29565 | EB35: =+DZ35/O35 -> 0 | ED35: =+DZ35*1.15 -> 0 | EE35: CPC | EF35: =+EG35/DX35 -> 0 | EG35: =+EN35 -> 0 | EH35: =IFERROR((+DZ35/EG35*1000),"") | EI35: =IFERROR(+DZ35/EO35,"") | EJ35: =+IFERROR(+DZ35/EN35,"") | EK35: =IFERROR(+(+DZ35/EP35*1000),"") | EQ35: =+IFERROR(+EN35/EP35,"") | ER35: =IFERROR(+EO35/EP35,"") | ES35: JOB:DCEEA5A10068_MKT:MKT0022145_MARCA:DC_PLATAFORMA:META_FECHA:27022026_CAMPAÑA:VACCOSTA2026_ETAPA:LAYER02_COMPRA:CPC_COMUNICACION:HOTELES_FORMATO:DINAMICOS_AUDIENCIA:RMK | ET35: EN PAUTA | EV35: https://www.dinersclub.com.ec/blubenefits/?utm_source=META&utm_medium=CPC&utm_campaign=DINERS-VACCOSTA-2026-MKT0022145&utm_id=DINERS-VACCOSTA-2026-MKT0022145&utm_term=DINERS-VACCOSTA-2026-MKT0022145&utm_content=META-DINAMICOS | EX35: NUEVO PPTO
E36: TIKTOK | F36: INFEED | G36: ESPECIALIDADES HOTELES Snackables con EXPERIENCIAS de amenities y beneficios | H36: BASE SOCIOS DINERS (EXC RMK VISUALIZACIÓN HOTELES) REGION COSTA | I36: 109000 | J36: CPV | K36: =+N36/$N$84 -> 0.017957479 | M36: =+N36 -> 548.2933 | N36: =398.293296+100+50 -> 548.2933 | O36: =+N36/1.05 -> 522.18409 | P36: 45.16 | R36: 398.2933 | S36: =R36/1.05 -> 379.32695 | AD36: =+O36*20% -> 104.43682 | AI36: =+O36*50% -> 261.09205 | BK36: =+O36*30% -> 156.65523 | DW36: 0.1 | DX36: =O36/DW36 -> 5221.8409 | DZ36: 285.93 | EA36: =+O36-DZ36 -> 236.25409 | EB36: =+DZ36/O36 -> 0.54756551 | EC36: 46079 | ED36: =+DZ36*1.15 -> 328.8195 | EE36: CPV | EF36: =+EG36/DX36 -> 2.0668956 | EG36: =+EO36 -> 10793 | EH36: =IFERROR((+DZ36/EG36*1000),"") -> 26.492171 | EI36: =IFERROR(+DZ36/EO36,"") -> 0.026492171 | EJ36: =+IFERROR(+DZ36/EN36,"") -> 0.34120525 | EK36: =IFERROR(+(+DZ36/EP36*1000),"") -> 0.97776243 | EL36: 65409 | EM36: 4.47 | EN36: 838 | EO36: 10793 | EP36: 292433 | EQ36: =+IFERROR(+EN36/EP36,"") -> 0.0028656137 | ER36: =IFERROR(+EO36/EP36,"") -> 0.036907599 | ES36: JOB:DCEEA5A10068_MKT:MKT0022145_MARCA:DC_PLATAFORMA:TIKTOK_FECHA:27012026_CAMPAÑA:VACCOSTA2026_ETAPA:LAYER02_COMPRA:CPV_COMUNICACION:HOTELES_FORMATO:INFEED_AUDIENCIA:BASESOCIOS | ET36: EN PAUTA | EU36: Se duplico el 24 de feb, por que se desactivaron todas las campañas de TikTok. | EV36: https://www.dinersclub.com.ec/blubenefits/?utm_source=TIKTOK&utm_medium=CPV&utm_campaign=DINERS-VACCOSTA-2026-MKT0022145&utm_id=DINERS-VACCOSTA-2026-MKT0022145&utm_term=DINERS-VACCOSTA-2026-MKT0022145&utm_content=TIKTOK-INFEED | EW36: 150.18 | EX36: =O36-EW36 -> 372.00409
H37: RMK WEB/RMK INTERACCIÓN RRSS (EXC RMK VISUALIZACIÓN HOTELES) REGION COSTA | I37: 155000 | K37: =+N37/$N$84 -> 0.01629195 | M37: =+N37 -> 497.43994 | N37: =347.439944+100+50 -> 497.43994 | O37: =+N37/1.05 -> 473.75233 | P37: 52.71 | R37: 347.43994 | S37: =R37/1.05 -> 330.89518 | AD37: =+O37*20% -> 94.750466 | AI37: =+O37*50% -> 236.87616 | BK37: =+O37*30% -> 142.1257 | DW37: 0.1 | DX37: =O37/DW37 -> 4737.5233 | DZ37: 264.97 | EA37: =+O37-DZ37 -> 208.78233 | EB37: =+DZ37/O37 -> 0.55930068 | EC37: 46079 | ED37: =+DZ37*1.15 -> 304.7155 | EE37: CPV | EF37: =+EG37/DX37 -> 4.5162839 | EG37: =+EO37 -> 21396 | EH37: =IFERROR((+DZ37/EG37*1000),"") -> 12.38409 | EI37: =IFERROR(+DZ37/EO37,"") -> 0.01238409 | EJ37: =+IFERROR(+DZ37/EN37,"") -> 0.13800521 | EK37: =IFERROR(+(+DZ37/EP37*1000),"") -> 0.66577217 | EL37: 117703 | EM37: 3.38 | EN37: 1920 | EO37: 21396 | EP37: 397989 | EQ37: =+IFERROR(+EN37/EP37,"") -> 0.0048242539 | ER37: =IFERROR(+EO37/EP37,"") -> 0.05376028 | ES37: JOB:DCEEA5A10068_MKT:MKT0022145_MARCA:DC_PLATAFORMA:TIKTOK_FECHA:27012026_CAMPAÑA:VACCOSTA2026_ETAPA:LAYER02_COMPRA:CPV_COMUNICACION:HOTELES_FORMATO:INFEED_AUDIENCIA:RMK | ET37: EN PAUTA | EV37: https://www.dinersclub.com.ec/blubenefits/?utm_source=TIKTOK&utm_medium=CPV&utm_campaign=DINERS-VACCOSTA-2026-MKT0022145&utm_id=DINERS-VACCOSTA-2026-MKT0022145&utm_term=DINERS-VACCOSTA-2026-MKT0022145&utm_content=TIKTOK-INFEED | EW37: 171.53 | EX37: =O37-EW37 -> 302.22233
E38: YOUTUBE | F38: INSTREAM | G38: ESPECIALIDADES HOTELES Snackables con EXPERIENCIAS de amenities y beneficios | H38: BASE SOCIOS DINERS (EXC RMK VISUALIZACIÓN HOTELES) REGION COSTA | I38: 54000 | J38: CPV | K38: =+N38/$N$84 -> 0.0045293257 | M38: =+N38 -> 138.2933 | N38: =298.293296-160-30+30 -> 138.2933 | O38: =+N38/1.05 -> 131.7079 | R38: 298.2933 | S38: =R38/1.05 -> 284.08885 | AD38: =+O38*20% -> 26.34158 | AI38: =+O38*50% -> 65.85395 | BK38: =+O38*30% -> 39.51237 | DW38: 1 | DX38: =O38/DW38 -> 131.7079 | EA38: =+O38-DZ38 -> 131.7079 | EB38: =+DZ38/O38 -> 0 | ED38: =+DZ38*1.15 -> 0 | EE38: CPV | EF38: =+EG38/DX38 -> 0 | EG38: =+EO38 -> 0 | EH38: =IFERROR((+DZ38/EG38*1000),"") | EI38: =IFERROR(+DZ38/EO38,"") | EJ38: =+IFERROR(+DZ38/EN38,"") | EK38: =IFERROR(+(+DZ38/EP38*1000),"") | EQ38: =+IFERROR(+EN38/EP38,"") | ER38: =IFERROR(+EO38/EP38,"") | ES38: JOB:DCEEA5A10068_MKT:MKT0022145_MARCA:DC_PLATAFORMA:YOUTUBE_FECHA:02032026_CAMPAÑA:VACCOSTA2026_ETAPA:LAYER02_COMPRA:CPV_COMUNICACION:HOTELES_FORMATO:INSTREAM_AUDIENCIA:BASESOCIOS | ET38: PENDIENTE APROBACION | EV38: www.dinersclub.com.ec/blubenefits/?utm_source=YOUTUBE&utm_medium=CPV&utm_campaign=DINERS-VACCOSTA-2026-MKT0022145&utm_id=DINERS-VACCOSTA-2026-MKT0022145&utm_term=DINERS-VACCOSTA-2026-MKT0022145&utm_content=YOUTUBE-INSTREAM
H39: RMK WEB/RMK INTERACCIÓN RRSS (EXC RMK VISUALIZACIÓN HOTELES) REGION COSTA | I39: - | K39: =+N39/$N$84 -> 0.0064664726 | M39: =+N39 -> 197.43994 | N39: =247.439944-100+50 -> 197.43994 | O39: =+N39/1.05 -> 188.03804 | R39: 247.43994 | S39: =R39/1.05 -> 235.65709 | AD39: =+O39*20% -> 37.607608 | AI39: =+O39*50% -> 94.019021 | BK39: =+O39*30% -> 56.411413 | DW39: 1 | DX39: =O39/DW39 -> 188.03804 | EA39: =+O39-DZ39 -> 188.03804 | EB39: =+DZ39/O39 -> 0 | ED39: =+DZ39*1.15 -> 0 | EE39: CPV | EF39: =+EG39/DX39 -> 0 | EG39: =+EO39 -> 0 | EH39: =IFERROR((+DZ39/EG39*1000),"") | EI39: =IFERROR(+DZ39/EO39,"") | EJ39: =+IFERROR(+DZ39/EN39,"") | EK39: =IFERROR(+(+DZ39/EP39*1000),"") | EQ39: =+IFERROR(+EN39/EP39,"") | ER39: =IFERROR(+EO39/EP39,"") | ES39: JOB:DCEEA5A10068_MKT:MKT0022145_MARCA:DC_PLATAFORMA:YOUTUBE_FECHA:02032026_CAMPAÑA:VACCOSTA2026_ETAPA:LAYER02_COMPRA:CPV_COMUNICACION:HOTELES_FORMATO:INSTREAM_AUDIENCIA:RMK | ET39: PENDIENTE APROBACION | EV39: www.dinersclub.com.ec/blubenefits/?utm_source=YOUTUBE&utm_medium=CPV&utm_campaign=DINERS-VACCOSTA-2026-MKT0022145&utm_id=DINERS-VACCOSTA-2026-MKT0022145&utm_term=DINERS-VACCOSTA-2026-MKT0022145&utm_content=YOUTUBE-INSTREAM
D40: AGENCIAS DE VIAJE | E40: META | F40: REEL/VIDEO AD | G40: ESPECIALIDADES AGENCIAS DE VIAJES Seguridad de tener todo | H40: BASE SOCIOS DINERS (EXC RMK VISUALIZACIÓN VIAJES) REGION COSTA | I40: 266000 | J40: CPV TRUVIEW 2 SEG | K40: =+N40/$N$84 -> 0.025192641 | M40: =+N40 -> 769.20354 | N40: =(198.862197333209*70%)+300+150+50+30+100 -> 769.20354 | O40: =+N40/1.15 -> 668.87264 | P40: 87.13 | R40: 669.20354 | S40: =R40/1.15 -> 581.91612 | AD40: =+O40*20% -> 133.77453 | AI40: =+O40*50% -> 334.43632 | BK40: =+O40*30% -> 200.66179 | DW40: 0.09 | DX40: =O40/DW40 -> 7431.9182 | DZ40: 571.88 | EA40: =+O40-DZ40 -> 96.992642 | EB40: =+DZ40/O40 -> 0.85499087 | EC40: 46079 | ED40: =+DZ40*1.15 -> 657.662 | EE40: CPV | EF40: =+EG40/DX40 -> 69.306871 | EG40: =+EP40 -> 515083 | EH40: =IFERROR((+DZ40/EG40*1000),"") -> 1.1102677 | EI40: =IFERROR(+DZ40/EO40,"") -> 0.076546647 | EJ40: =+IFERROR(+DZ40/EN40,"") -> 2.125948 | EK40: =IFERROR(+(+DZ40/EP40*1000),"") -> 1.1102677 | EL40: 99756 | EM40: 5.16 | EN40: 269 | EO40: 7471 | EP40: 515083 | EQ40: =+IFERROR(+EN40/EP40,"") -> 0.00052224593 | ER40: =IFERROR(+EO40/EP40,"") -> 0.014504459 | ES40: JOB:DCEEA5A10068_MKT:MKT0022145_MARCA:DC_PLATAFORMA:META_FECHA:27012026_CAMPAÑA:VACCOSTA2026_ETAPA:LAYER02_COMPRA:CPV_COMUNICACION:VIAJES_FORMATO:VIDEOADREEL_AUDIENCIA:BASESOCIOS | ET40: EN PAUTA | EU40: se aumento el creativo de tiktok el 11 de feb | EV40: https://www.dinersclub.com.ec/blubenefits/?utm_source=META&utm_medium=CPV&utm_campaign=DINERS-VACCOSTA-2026-MKT0022145&utm_id=DINERS-VACCOSTA-2026-MKT0022145&utm_term=DINERS-VACCOSTA-2026-MKT0022145&utm_content=META-VIDEOADREEL | FD40: CAMBIO DE PIEZAS DE LOS VIDEOAD/REELS DE TODAS LAS CATEGORÍAS
H41: RMK WEB/RMK INTERACCIÓN RRSS (EXC RMK VISUALIZACIÓN VIAJES) REGION COSTA | I41: 155000 | K41: =+N41/$N$84 -> 0.02419705 | M41: =+N41 -> 738.80531 | N41: =(298.293295999814*70%)+300+100+30+100 -> 738.80531 | O41: =+N41/1.15 -> 642.4394 | P41: 88.31 | R41: 638.80531 | S41: =R41/1.15 -> 555.48288 | AD41: =+O41*20% -> 128.48788 | AI41: =+O41*50% -> 321.2197 | BK41: =+O41*30% -> 192.73182 | DW41: 0.09 | DX41: =O41/DW41 -> 7138.2155 | DZ41: 547.39 | EA41: =+O41-DZ41 -> 95.049398 | EB41: =+DZ41/O41 -> 0.85204924 | EC41: 46079 | ED41: =+DZ41*1.15 -> 629.4985 | EE41: CPV | EF41: =+EG41/DX41 -> 156.56112 | EG41: =+EP41 -> 1117567 | EH41: =IFERROR((+DZ41/EG41*1000),"") -> 0.48980509 | EI41: =IFERROR(+DZ41/EO41,"") -> 0.029789932 | EJ41: =+IFERROR(+DZ41/EN41,"") -> 1.3286165 | EK41: =IFERROR(+(+DZ41/EP41*1000),"") -> 0.48980509 | EL41: 254008 | EM41: 4.4 | EN41: 412 | EO41: 18375 | EP41: 1117567 | EQ41: =+IFERROR(+EN41/EP41,"") -> 0.00036865799 | ER41: =IFERROR(+EO41/EP41,"") -> 0.016441967 | ES41: JOB:DCEEA5A10068_MKT:MKT0022145_MARCA:DC_PLATAFORMA:META_FECHA:27012026_CAMPAÑA:VACCOSTA2026_ETAPA:LAYER02_COMPRA:CPV_COMUNICACION:VIAJES_FORMATO:VIDEOADREEL_AUDIENCIA:RMK | ET41: EN PAUTA | EU41: se aumento el creativo de tiktok el 11 de feb | EV41: https://www.dinersclub.com.ec/blubenefits/?utm_source=META&utm_medium=CPV&utm_campaign=DINERS-VACCOSTA-2026-MKT0022145&utm_id=DINERS-VACCOSTA-2026-MKT0022145&utm_term=DINERS-VACCOSTA-2026-MKT0022145&utm_content=META-VIDEOADREEL
E42: META | F42: DINAMICOS | G42: ESPECIALIDADES AGENCIAS DE VIAJES Seguridad de tener todo | H42: BASE SOCIOS DINERS (EXC RMK VISUALIZACIÓN VIAJES) REGION COSTA | I42: 266000 | J42: CPC | K42: =+N42/$N$84 -> 0.0035914957 | M42: =+N42 -> 109.65866 | N42: =(198.862197333209*30%)+50 -> 109.65866 | O42: =+N42/1.15 -> 95.355356 | R42: 59.658659 | S42: =R42/1.15 -> 51.877095 | AD42: =+O42*20% -> 19.071071 | AI42: =+O42*50% -> 47.677678 | BK42: =+O42*30% -> 28.606607 | DW42: 0.09 | DX42: =O42/DW42 -> 1059.504 | EA42: =+O42-DZ42 -> 95.355356 | EB42: =+DZ42/O42 -> 0 | ED42: =+DZ42*1.15 -> 0 | EE42: CPC | EF42: =+EG42/DX42 -> 0 | EG42: =+EP42 -> 0 | EH42: =IFERROR((+DZ42/EG42*1000),"") | EI42: =IFERROR(+DZ42/EO42,"") | EJ42: =+IFERROR(+DZ42/EN42,"") | EK42: =IFERROR(+(+DZ42/EP42*1000),"") | EQ42: =+IFERROR(+EN42/EP42,"") | ER42: =IFERROR(+EO42/EP42,"") | ES42: JOB:DCEEA5A10068_MKT:MKT0022145_MARCA:DC_PLATAFORMA:META_FECHA:27022026_CAMPAÑA:VACCOSTA2026_ETAPA:LAYER02_COMPRA:CPC_COMUNICACION:VIAJES_FORMATO:DINAMICOS_AUDIENCIA:BASESOCIOS | ET42: EN PAUTA | EV42: https://www.dinersclub.com.ec/blubenefits/?utm_source=META&utm_medium=CPV&utm_campaign=DINERS-VACCOSTA-2026-MKT0022145&utm_id=DINERS-VACCOSTA-2026-MKT0022145&utm_term=DINERS-VACCOSTA-2026-MKT0022145&utm_content=META-DINAMICOS
H43: RMK WEB/RMK INTERACCIÓN RRSS (EXC RMK VISUALIZACIÓN VIAJES) REGION COSTA | I43: 155000 | K43: =+N43/$N$84 -> 0.0045684538 | M43: =+N43 -> 139.48799 | N43: =(298.293295999814*30%)+50 -> 139.48799 | O43: =+N43/1.15 -> 121.2939 | R43: 89.487989 | S43: =R43/1.15 -> 77.815642 | AD43: =+O43*20% -> 24.258781 | AI43: =+O43*50% -> 60.646952 | BK43: =+O43*30% -> 36.388171 | DW43: 0.09 | DX43: =O43/DW43 -> 1347.71 | EA43: =+O43-DZ43 -> 121.2939 | EB43: =+DZ43/O43 -> 0 | ED43: =+DZ43*1.15 -> 0 | EE43: CPC | EF43: =+EG43/DX43 -> 0 | EG43: =+EP43 -> 0 | EH43: =IFERROR((+DZ43/EG43*1000),"") | EI43: =IFERROR(+DZ43/EO43,"") | EJ43: =+IFERROR(+DZ43/EN43,"") | EK43: =IFERROR(+(+DZ43/EP43*1000),"") | EQ43: =+IFERROR(+EN43/EP43,"") | ER43: =IFERROR(+EO43/EP43,"") | ES43: JOB:DCEEA5A10068_MKT:MKT0022145_MARCA:DC_PLATAFORMA:META_FECHA:27022026_CAMPAÑA:VACCOSTA2026_ETAPA:LAYER02_COMPRA:CPC_COMUNICACION:VIAJES_FORMATO:DINAMICOS_AUDIENCIA:RMK | ET43: EN PAUTA | EV43: https://www.dinersclub.com.ec/blubenefits/?utm_source=META&utm_medium=CPV&utm_campaign=DINERS-VACCOSTA-2026-MKT0022145&utm_id=DINERS-VACCOSTA-2026-MKT0022145&utm_term=DINERS-VACCOSTA-2026-MKT0022145&utm_content=META-DINAMICOS | EX43: NUEVO PPTO
...

Sheet SHARE
C3: VAC COSTA 2026
C5: TOTAL ICLUIDO FEE - DIGITAL | F5: 24600
C6: TOTAL ICLUIDO FEE | F6: 80000
F8: TOTAL + FEE
C9: AWARENESS | F9: =+F6+F5 -> 104600
C10: TELEVISION | E10: =+'FLOW MEDIOS'!X10 -> 45620 | F10: =+E10/F9 -> 0.43613767
C11: DIGITAL | E11: 34460 | F11: =+E11/F9 -> 0.32944551
C12: VIA PÚBLICA | E12: =+'FLOW MEDIOS'!X13 -> 13000 | F12: =+E12/F9 -> 0.12428298
C13: RADIO | F13: =+E13/F9 -> 0
C14: PANTALLAS LED | F14: =+E14/F9 -> 0
C15: REVISTA | E15: =+F9*F15 -> 0 | F15: 0
C16: CINE | E16: =+F9*F16 -> 0 | F16: 0
C17: TOTAL | D17: =SUM(D16:D16) -> 0 | E17: =SUM(E10:E16) -> 93080 | F17: =SUM(F10:F16) -> 0.88986616
E19: =+F9-E17 -> 11520
C21: TELEVISIÓN
C22: ECUAVISA | D22: 27600
C23: TC | D23: 18000
D24: =+D22+D23 -> 45600
C28: SHARE DIGITAL
C29: TOTAL | D29: =+E11 -> 34460
C30: FEE PRIMICIAS | D30: 2500
C31: SUBTOTAL | D31: =+D29-D30 -> 31960
C32: INVERSION ANTES DE FEE | D32: =+D31/1.2 -> 26633.333

Sheet PAUTA TELEVISIÓN OP1 
C3: CLIENTE: | D3: BANCO DINERS DEL ECUADOR
C4: PRODUCTO: | D4: DINERS CLUB | K4: PAUTA DE TELEVISIÓN
C5: CAMPAÑA: | D5: VAC COSTA
C6: TARGET: | D6: PERSONAS AB
K7: 1 | R7: 2 | Y7: 3 | AF7: 4 | AM7: 5 | AT7: 6 | BA7: 6 | BH7: 7 | BO7: 9 | BV7: 10 | CH7: =CH8/CJ8 -> 0.57213533 | CI7: =CI8/CJ8 -> 0.42786467 | CJ7: UNIV
K8: ENERO | X8: FEBRERO | AY8: MARZO | CH8: 1246660 | CI8: 932300 | CJ8: 2178960
C9: PROGRAMA | D9: HORA | E9: GENERO | F9: DÍAS | G9: FRANJA | H9: MENSAJE | I9: FORMATO | J9: SEG | K9: L | L9: M | M9: X | N9: J | O9: V | P9: S | Q9: D | R9: L | S9: M | T9: X | U9: J | V9: V | W9: S | X9: D | Y9: L | Z9: M | AA9: X | AB9: J | AC9: V | AD9: S | AE9: D | AF9: L | AG9: M | AH9: X | AI9: J | AJ9: V | AK9: S | AL9: D | AM9: L | AN9: M | AO9: X | AP9: J | AQ9: V | AR9: S | AS9: D | AT9: L | AU9: M | AV9: X | AW9: J | AX9: V | AY9: S | AZ9: D | BA9: L | BB9: M | BC9: X | BD9: J | BE9: V | BF9: S | BG9: D | BH9: L | BI9: M | BJ9: X | BK9: J | BL9: V | BM9: S | BN9: D | BO9: L | BP9: M | BQ9: X | BR9: J | BS9: V | BT9: S | BU9: D | BV9: L | BW9: M | BX9: X | BY9: J | BZ9: V | CA9: S | CB9: D | CC9: L | CD9: TOTAL | CE9: Rtg Personas AB | CH9: Trp´s Personas AB | CM9: TARIFA REAL | CO9: TARIFA NEG | CP9: INVERSIÓN REAL | CQ9: INVERSIÓN NEGOCIADA | CR9: Costo Trp´s | CT9: AWARENESS | CV9: MOVILIZACIÓN
K10: 19 | L10: =K10+1 -> 20 | M10: =L10+1 -> 21 | N10: =M10+1 -> 22 | O10: =N10+1 -> 23 | P10: =O10+1 -> 24 | Q10: =P10+1 -> 25 | R10: =Q10+1 -> 26 | S10: =R10+1 -> 27 | ... V10: =U10+1 -> 30 | W10: 31 | X10: 1 | Y10: =X10+1 -> 2 | Z10: =Y10+1 -> 3 | AA10: =Z10+1 -> 4 | AB10: =AA10+1 -> 5 | AC10: =AB10+1 -> 6 | AD10: =AC10+1 -> 7 | AE10: =AD10+1 -> 8 | AF10: =AE10+1 -> 9 | ... AX10: =AW10+1 -> 27 | AY10: 1 | AZ10: =AY10+1 -> 2 | BA10: =AZ10+1 -> 3 | BB10: =BA10+1 -> 4 | BC10: =BB10+1 -> 5 | BD10: =BC10+1 -> 6 | BE10: =BD10+1 -> 7 | BF10: =BE10+1 -> 8 | BG10: =BF10+1 -> 9 | ... CC10: =CB10+1 -> 31 | CD10: CUÑAS | CE10: UIO | CF10: GYE | CG10: NAC | CH10: UIO | CI10: GYE | CJ10: NAC | CT10: ENERO | CU10: FEBRERO | CV10: FEBRERO 20SEG | CX10: 1 | DA10: 2 | DD10: 3 | DG10: 4 | DJ10: 5 | DM10: 6 | DP10: 7
C11: ECUAVISA 8 - QUITO | AM11: FERIADO | CX11: UIO | CY11: GYE | CZ11: NAC | DA11: UIO | DB11: GYE | DC11: NAC | DD11: UIO | DE11: GYE | DF11: NAC | DG11: UIO | DH11: GYE | DI11: NAC | DJ11: UIO | DK11: GYE | DL11: NAC | DM11: UIO | DN11: GYE | DO11: NAC | DP11: UIO | DQ11: GYE | DR11: NAC
C12: TELEVISTAZO AL AMANECER | D12: 0.25 | E12: NOTICIERO | F12: LMWJV | G12: =IF(D12<=0.541,"DAY",(IF(D12<=0.74930556,"EARLY",(IF(D12<=0.97916667,"PRIME","LATE"))))) -> DAY | H12: AWARENESS | I12: SPOT | J12: 40 | K12: 1 | M12: 1 | R12: 1 | T12: 1 | V12: 1 | CD12: =SUM(K12:CC12) -> 5 | CE12: 2.7 | CG12: =(CE12*$CH$7)+(CF12*$CI$7) -> 1.5447654 | CH12: =+CD12*CE12 -> 13.5 | CI12: =+CD12*CF12 -> 0 | CJ12: =CD12*CG12 -> 7.723827 | CK12: =2673/2 -> 1336.5 | CL12: =2673/2 -> 1336.5 | CM12: =CL12/30*J12 -> 1782 | CO12: 345 | CP12: =CM12*CD12 -> 8910 | CQ12: =CO12*CD12 -> 1725 | CR12: =CQ12/CJ12 -> 223.33488 | CT12: =SUM(K12:W12)*CO12 -> 1725 | CU12: =SUM(X12:AX12)*CO12 -> 0 | CX12: =COUNTA(R12:X12)*$CE12 -> 8.1 | CY12: =COUNTA(R12:X12)*$CF12 -> 0 | CZ12: =COUNTA(K12:Q12)*$CG12 -> 3.0895308 | DA12: =COUNTA(Y12:AE12)*$CE12 -> 0 | DB12: =COUNTA(Y12:AE12)*$CF12 -> 0 | DC12: =COUNTA(R12:X12)*$CG12 -> 4.6342962 | DD12: =COUNTA(AF12:AL12)*$CE12 -> 0 | DE12: =COUNTA(AF12:AL12)*$CF12 -> 0 | DF12: =COUNTA(Y12:AE12)*$CG12 -> 0 | DG12: =COUNTA(AM12:AS12)*$CE12 -> 0 | DH12: =COUNTA(AM12:AS12)*$CF12 -> 0 | DI12: =COUNTA(AF12:AL12)*$CG12 -> 0 | DJ12: =COUNTA(AT12:AZ12)*$CE12 -> 0 | DK12: =COUNTA(AT12:AZ12)*$CF12 -> 0 | DL12: =COUNTA(AM12:AS12)*$CG12 -> 0 | DM12: =COUNTA(BA12:BG12)*$CE12 -> 0 | DN12: =COUNTA(BA12:BG12)*$CF12 -> 0 | DO12: =COUNTA(AT12:AX12)*$CG12 -> 0 | DP12: =COUNTA(BH12:BN12)*$CE12 -> 0 | DQ12: =COUNTA(BH12:BN12)*$CF12 -> 0 | DR12: =COUNTA(BH12:BN12)*$CG12 -> 0
